Workbook

Sheet 표지
F3: 에스텍 그룹
A5: 현대자동차 울산공장 정문 보안용역 도급업무
A6: 見 積 書
A7: 2027년 용역 도급 견적서 · Q U O T A T I O N
A30: 투입 인력 구성
A35: ="보안(경비) "&(N('견적서'!F28)+N('견적서'!F29)+N('견적서'!F30))&"명"&" ("&"실장 "&(N('견적서'!F28))&" · "&"팀장 "&(N('견적서'!F29))&" · "&"요원 "&(N('견적서'!F30))&")" -> 보안(경비) 13명 (실장 1 · 팀장 3 · 요원 9)
B37: 수 신 | D37: 현대자동차 울산공장 정문 貴中
B38: 용 역 명 | D38: 보안용역 도급업무
B39: 용역기간 | D39: 2027. 1. 1 ~ 2027. 12. 31 (12개월)
B40: 견적금액 | D40: ="월 "&TEXT('견적서'!I31,"#,##0")&"원 (VAT 별도) · "&'견적서'!F31&"명" -> 월 56,928,000원 (VAT 별도) · 13명
B41: 견적기준 | D41: 2027년 최저임금 10,700원 · 4대보험 법정요율
A43: 2026년 10월
F45: ㈜에스텍시스템 에스텍 그룹
A47: 서울특별시 강남구 개포로 619, 8층(개포동, 서울강남우체국청사) ·

Sheet 견적서
D1: 견 적 서 | I1: No. 261021-2703
I2: 작성일 2026. 10. 21
D3: Q U O T A T I O N
A7: 현대자동차 울산공장 정문 貴中 | F7: 등록번호 | G7: 202-81-62708
A8: 용 역 명 | C8: 보안용역 도급업무 | F8: 상 호 | G8: ㈜에스텍시스템 | H8: 대 표 | I8: 이병화 (인)
A9: 용역기간 | C9: 2027. 1. 1 ~ 2027. 12. 31 (12개월) | F9: 주 소 | G9: 서울특별시 강남구 개포로 619, 8층(개포동, 서울강남우체국청사)
A10: 유효기간 | C10: 작성일로부터 1개월 | F10: 업 태 | G10: 서비스 | H10: 종 목 | I10: 시설경비·신변보호·기계경비·호송경비, 건물(시설)관리용역, 위생관리, 주차관리
A11: 사 업 장 | C11: 울산 북구 염포로 700 | F11: 허가·신고
A12: 귀사의 무궁한 발전을 기원하며, 아래와 같이 견적합니다. | F12: 담 당 | G12: 에스텍 그룹
A14: 견적금액 · 월 (VAT 별도) | G14: ="부가세 포함 월 "&TEXT(I33,"#,##0")&"원 · "&F31&"명 / 평균 "&TEXT(IF(N(F31)=0,0,SUM(I28:I30)/F31),"#,##0")&"원" -> 부가세 포함 월 62,620,800원 · 13명 / 평균 4,379,077원
A15: =I31 -> 56928000 | D15: ="일금 "&IF(ROUND(ABS(N(I31)),0)=0,"영",CHOOSE(VALUE(MID(TEXT(ROUND(ABS(N(I31)),0),"000000000000"),1,1))+1,"","일","이","삼","사","오","육","칠","팔","구")&IF(MID(TEXT(ROUND(ABS(N(I31)),0),"000000000000"),1,1)="0","","천")&CHOOSE(VALUE(MID(TEXT(ROUND(ABS(N(I31)),0),"000000000000"),2,1))+1,"","일","이","삼","사","오","육","칠","팔","구")&IF(MID(TEXT(ROUND(ABS(N(I31)),0),"000000000000"),2,1)="0","","백")&CHOOSE(VALUE(MID(TEXT(ROUND(ABS(N(I31)),0),"000000000000"),3,1))+1,"","일","이","삼","사","오","육","칠","팔","구")&IF(MID(TEXT(ROUND(ABS(N(I31)),0),"000000000000"),3,1)="0","","십")&CHOOSE(VALUE(MID(TEXT(ROUND(ABS(N(I31)),0),"000000000000"),4,1))+1,"","일","이","삼","사","오","육","칠","팔","구")&IF(MID(TEXT(ROUND(ABS(N(I31)),0),"000000000000"),4,1)="0","","")&IF(MID(TEXT(ROUND(ABS(N(I31)),0),"000000000000"),1,4)="0000","","억")&CHOOSE(VALUE(MID(TEXT(ROUND(ABS(N(I31)),0),"000000000000"),5,1))+1,"","일","이","삼","사","오","육","칠","팔","구")&IF(MID(TEXT(ROUND(ABS(N(I31)),0),"000000000000"),5,1)="0","","천")&CHOOSE(VALUE(MID(TEXT(ROUND(ABS(N(I31)),0),"000000000000"),6,1))+1,"","일","이","삼","사","오","육","칠","팔","구")&IF(MID(TEXT(ROUND(ABS(N(I31)),0),"000000000000"),6,1)="0","","백")&CHOOSE(VALUE(MID(TEXT(ROUND(ABS(N(I31)),0),"000000000000"),7,1))+1,"","일","이","삼","사","오","육","칠","팔","구")&IF(MID(TEXT(ROUND(ABS(N(I31)),0),"000000000000"),7,1)="0","","십")&CHOOSE(VALUE(MID(TEXT(ROUND(ABS(N(I31)),0),"000000000000"),8,1))+1,"","일","이","삼","사","오","육","칠","팔","구")&IF(MID(TEXT(ROUND(ABS(N(I31)),0),"000000000000"),8,1)="0","","")&IF(MID(TEXT(ROUND(ABS(N(I31)),0),"000000000000"),5,4)="0000","","만")&CHOOSE(VALUE(MID(TEXT(ROUND(ABS(N(I31)),0),"000000000000"),9,1))+1,"","일","이","삼","사","오","육","칠","팔","구")&IF(MID(TEXT(ROUND(ABS(N(I31)),0),"000000000000"),9,1)="0","","천")&CHOOSE(VALUE(MID(TEXT(ROUND(ABS(N(I31)),0),"000000000000"),10,1))+1,"","일","이","삼","사","오","육","칠","팔","구")&IF(MID(TEXT(ROUND(ABS(N(I31)),0),"000000000000"),10,1)="0","","백")&CHOOSE(VALUE(MID(TEXT(ROUND(ABS(N(I31)),0),"000000000000"),11,1))+1,"","일","이","삼","사","오","육","칠","팔","구")&IF(MID(TEXT(ROUND(ABS(N(I31)),0),"000000000000"),11,1)="0","","십")&CHOOSE(VALUE(MID(TEXT(ROUND(ABS(N(I31)),0),"000000000000"),12,1))+1,"","일","이","삼","사","오","육","칠","팔","구")&IF(MID(TEXT(ROUND(ABS(N(I31)),0),"000000000000"),12,1)="0","",""))&"원정" -> 일금 오천육백구십이만팔천원정 | G15: ="계약기간 12개월 총액 "&TEXT(I34,"#,##0")&"원 (VAT 별도)" -> 계약기간 12개월 총액 683,136,000원 (VAT 별도)
A17: ■ 투입 인력 구성
A22: ="보안(경비) "&(N(F28)+N(F29)+N(F30))&"명" -> 보안(경비) 13명
A23: ="실장 "&(N(F28))&" · "&"팀장 "&(N(F29))&" · "&"요원 "&(N(F30)) -> 실장 1 · 팀장 3 · 요원 9
A24: ="월 "&TEXT(N(I28)+N(I29)+N(I30),"#,##0")&"원" -> 월 56,928,000원
A26: ■ 견적 내역 | J26: (단위: 명, 원 / VAT 별도)
A27: No | B27: 직종 | C27: 직책 | D27: 근무지·직무 | E27: 운영형태 | F27: 인원 | H27: 2027년 단가 | I27: 월 합계 | J27: 비고
A28: 1 | B28: 보안 | C28: 실장 | E28: 주간 주5일 (11h·연장3h/일) | F28: ='산출내역서'!C10 -> 1 | H28: ='산출내역서'!C67 -> 4794000 | I28: =F28*H28 -> 4794000
A29: 2 | B29: 보안 | C29: 팀장 | E29: 주간 주5일 (11h·연장3h/일) | F29: ='산출내역서'!D10 -> 3 | H29: ='산출내역서'!D67 -> 4517000 | I29: =F29*H29 -> 13551000
A30: 3 | B30: 보안 | C30: 요원 | E30: 3조2교대 (12h) | F30: ='산출내역서'!E10 -> 9 | H30: ='산출내역서'!E67 -> 4287000 | I30: =F30*H30 -> 38583000
A31: 월 합계 | F31: =SUM(F28:F30) -> 13 | I31: =SUM(I28:I30) -> 56928000
A32: 부가가치세 (10%) | I32: =ROUND(I31*0.1,0) -> 5692800
A33: 월 총계 (VAT 포함) | I33: =I31+I32 -> 62620800
A34: 계약기간 총액 (VAT 별도 · 12개월) | I34: =I31*12 -> 683136000
A36: ■ 견적 조건
A37: ○ 견적 기준 : 2027년 최저임금(10,700원) 및 통상시급 적용
A38: 단, 매년 법정최저임금(4대보험 포함) 등 관계법령이 변경될 경우 그 즉시 변경된 내용에 따라 적용합니다.
A39: ○ 납입 조건 : 전자세금계산서 발행(당월 20일 청구, 익월 5일 납입, 현금결제)
A40: ○ 손해배상 : 총 2억원 (당사의 귀책사유로 인한 사고 발생시 손해배상 책임보험에 의거)
A41: 1) 대인배상 : 1인 2천만원 한도 총 1억원(1사고당), 2) 대물배상 : 1억원한도(사고당)
A42: ○ 상기 금액은 피복, 장비, 복리후생 등 포함한 금액입니다.
A43: ○ 업무 수행에 필요한 근무실, 휴게실, 청소용품(소모품 포함), 집기류, 통신, 식사는 고객사 제공조건
C46: ㈜에스텍시스템 · 에스텍 그룹 서울특별시 강남구 개포로 619, 8층(개포동, 서울강남우체국청사)

Sheet 산출내역서
D1: 2027년 현대자동차 울산공장 정문 산출내역서 | H1: No. 261021-2703
H2: 작성일 2026. 10. 21
D3: 보안용역 도급업무 · 용역기간 2027. 1. 1 ~ 2027. 12. 31 (12개월) · 단위: 원, VAT 별도 · 노란 칸 = 입력값(수정 시 자동 재계산)
A7: 구 분 | C7: 보안 | D7: 보안 | E7: 보안 | F7: 월간총액 | G7: 평균단가 | H7: 계약기간 계 | I7: 산출 근거 (수식)
C8: 실장 | D8: 팀장 | E8: 요원
C9: 주간 주5일 | D9: 주간 주5일 | E9: 3조2교대
A10: 기초자료 | B10: 인원(명) | C10: 1 | D10: 3 | E10: 9 | F10: =SUM(C10:E10) -> 13 | I10: 입력값
B11: 시급 | C11: 10700 | D11: 10700 | E11: 10700 | I11: 입력값
B12: 기본시간(주휴포함) | C12: 209 | D12: 209 | E12: 209 | I12: 입력값
B13: 연장근로시간 | C13: 65 | D13: 65 | E13: 25 | I13: 입력값
B14: 야간근로시간 | C14: 0 | D14: 0 | E14: 82 | I14: 입력값
B15: 공휴일근무(일/년) | C15: 0 | D15: 0 | E15: 0 | I15: 입력값
B16: 연차적치일수 | C16: 15 | D16: 15 | E16: 15 | I16: 입력값
B17: 상여율(연, 기본급 대비) | C17: 0 | D17: 0 | E17: 0 | I17: 입력값
B18: 상여 기준(0=기본급,1=통상임금) | C18: 0 | D18: 0 | E18: 0 | I18: 입력값
B19: 근로자의날 유급시간 | C19: 11 | D19: 11 | E19: 11 | I19: 입력값
B20: 감시단속(1=승인) | C20: 1 | D20: 1 | E20: 1 | I20: 입력값
B21: 퇴직충당금(1=반영) | C21: 1 | D21: 1 | E21: 1 | I21: 입력값
B22: 국민연금 적용률 | C22: 1 | D22: 1 | E22: 1 | I22: 입력값
... B25: 연간 근무개월 | C25: 12 | D25: 12 | E25: 12 | I25: 입력값
B26: 통상시급 | C26: =IF(C12=0,0,(C27+C30+C34+C32)/C12) -> 13092.344 | D26: =IF(D12=0,0,(D27+D30+D34+D32)/D12) -> 12135.407 | E26: =IF(E12=0,0,(E27+E30+E34+E32)/E12) -> 11178.469
A27: 직접인건비 | B27: 기본급여 | C27: =ROUNDUP(C12*C11,-1) -> 2236300 | D27: =ROUNDUP(D12*D11,-1) -> 2236300 | E27: =ROUNDUP(E12*E11,-1) -> 2236300 | F27: =SUMPRODUCT(C27:E27,C10:E10) -> 29071900 | G27: =IF($C$96=0,0,F27/$C$96) -> 2236300 | H27: =SUMPRODUCT(C27:E27,C10:E10,C25:E25) -> 348862800 | I27: ROUNDUP(시급 × 기본시간, -1)
B28: 연장근로수당 | C28: =IF(C13=0,0,ROUNDUP(C13*IF(C20=1,C11*$C$81,C26*$C$80),-1)) -> 695500 | D28: =IF(D13=0,0,ROUNDUP(D13*IF(D20=1,D11*$C$81,D26*$C$80),-1)) -> 695500 | E28: =IF(E13=0,0,ROUNDUP(E13*IF(E20=1,E11*$C$81,E26*$C$80),-1)) -> 267500 | F28: =SUMPRODUCT(C28:E28,C10:E10) -> 5189500 | G28: =IF($C$96=0,0,F28/$C$96) -> 399192.31 | H28: =SUMPRODUCT(C28:E28,C10:E10,C25:E25) -> 62274000 | I28: 감시단속: 시급×배율 / 일반: 통상시급×1.5 × 연장시간
B29: 야간가산수당 | C29: =ROUNDUP(C14*$C$82*C26,-1) -> 0 | D29: =ROUNDUP(D14*$C$82*D26,-1) -> 0 | E29: =ROUNDUP(E14*$C$82*E26,-1) -> 458320 | F29: =SUMPRODUCT(C29:E29,C10:E10) -> 4124880 | G29: =IF($C$96=0,0,F29/$C$96) -> 317298.46 | H29: =SUMPRODUCT(C29:E29,C10:E10,C25:E25) -> 49498560 | I29: ROUNDUP(야간근로시간 × 가산율 × 통상시급, -1)
B30: 직책수당 | C30: 0 | D30: 0 | E30: 0 | F30: =SUMPRODUCT(C30:E30,C10:E10) -> 0 | G30: =IF($C$96=0,0,F30/$C$96) -> 0 | H30: =SUMPRODUCT(C30:E30,C10:E10,C25:E25) -> 0
B31: 공휴일근무수당 | C31: =IF(C15=0,0,ROUNDUP(C11*C15*8*0.5/12,-1)) -> 0 | D31: =IF(D15=0,0,ROUNDUP(D11*D15*8*0.5/12,-1)) -> 0 | E31: =IF(E15=0,0,ROUNDUP(E11*E15*8*0.5/12,-1)) -> 0 | F31: =SUMPRODUCT(C31:E31,C10:E10) -> 0 | G31: =IF($C$96=0,0,F31/$C$96) -> 0 | H31: =SUMPRODUCT(C31:E31,C10:E10,C25:E25) -> 0 | I31: 시급 × 공휴일수 × 8h × 50% ÷ 12
B32: 직무수당 | C32: 500000 | D32: 300000 | E32: 0 | F32: =SUMPRODUCT(C32:E32,C10:E10) -> 1400000 | G32: =IF($C$96=0,0,F32/$C$96) -> 107692.31 | H32: =SUMPRODUCT(C32:E32,C10:E10,C25:E25) -> 16800000
B33: 식대(비과세) | C33: 0 | D33: 0 | E33: 0 | F33: =SUMPRODUCT(C33:E33,C10:E10) -> 0 | G33: =IF($C$96=0,0,F33/$C$96) -> 0 | H33: =SUMPRODUCT(C33:E33,C10:E10,C25:E25) -> 0
B34: 조정수당 | C34: 0 | D34: 0 | E34: 100000 | F34: =SUMPRODUCT(C34:E34,C10:E10) -> 900000 | G34: =IF($C$96=0,0,F34/$C$96) -> 69230.769 | H34: =SUMPRODUCT(C34:E34,C10:E10,C25:E25) -> 10800000
B35: 소 계 | C35: =SUM(C27:C34) -> 3431800 | D35: =SUM(D27:D34) -> 3231800 | E35: =SUM(E27:E34) -> 3062120 | F35: =SUMPRODUCT(C35:E35,C10:E10) -> 40686280 | G35: =IF($C$96=0,0,F35/$C$96) -> 3129713.8 | H35: =SUMPRODUCT(C35:E35,C10:E10,C25:E25) -> 488235360 | I35: 기본급여 ~ 조정수당 합계
B36: 연차수당(적치) | C36: =ROUNDUP(C26*$C$83*C16/12,-1) -> 130930 | D36: =ROUNDUP(D26*$C$83*D16/12,-1) -> 121360 | E36: =ROUNDUP(E26*$C$83*E16/12,-1) -> 111790 | F36: =SUMPRODUCT(C36:E36,C10:E10) -> 1501120 | G36: =IF($C$96=0,0,F36/$C$96) -> 115470.77 | H36: =SUMPRODUCT(C36:E36,C10:E10,C25:E25) -> 18013440 | I36: ROUNDUP(통상시급 × 연차1일시간 × 적치일수 ÷ 12, -1)
B37: 근로자의날 | C37: =ROUNDUP(C19/12*C26,-1) -> 12010 | D37: =ROUNDUP(D19/12*D26,-1) -> 11130 | E37: =ROUNDUP(E19/12*E26,-1) -> 10250 | F37: =SUMPRODUCT(C37:E37,C10:E10) -> 137650 | G37: =IF($C$96=0,0,F37/$C$96) -> 10588.462 | H37: =SUMPRODUCT(C37:E37,C10:E10,C25:E25) -> 1651800 | I37: ROUNDUP(유급시간 ÷ 12 × 통상시급, -1)
B38: 상여금 | C38: =IF(C17=0,0,ROUNDUP(IF(C18=1,C27+C30+C34+C32,C27)*C17/12,-1)) -> 0 | D38: =IF(D17=0,0,ROUNDUP(IF(D18=1,D27+D30+D34+D32,D27)*D17/12,-1)) -> 0 | E38: =IF(E17=0,0,ROUNDUP(IF(E18=1,E27+E30+E34+E32,E27)*E17/12,-1)) -> 0 | F38: =SUMPRODUCT(C38:E38,C10:E10) -> 0 | G38: =IF($C$96=0,0,F38/$C$96) -> 0 | H38: =SUMPRODUCT(C38:E38,C10:E10,C25:E25) -> 0 | I38: ROUNDUP(기본급(또는 통상임금) × 상여율 ÷ 12, -1)
B39: 퇴직충당금 | C39: =IF(C21=1,ROUNDUP((C35+C36+C37+C38)/12,-1),0) -> 297900 | D39: =IF(D21=1,ROUNDUP((D35+D36+D37+D38)/12,-1),0) -> 280360 | E39: =IF(E21=1,ROUNDUP((E35+E36+E37+E38)/12,-1),0) -> 265350 | F39: =SUMPRODUCT(C39:E39,C10:E10) -> 3527130 | G39: =IF($C$96=0,0,F39/$C$96) -> 271317.69 | H39: =SUMPRODUCT(C39:E39,C10:E10,C25:E25) -> 42325560 | I39: ROUNDUP((소계+연차+근로자의날+상여금) ÷ 12, -1)
B40: 직접비 계 ① | C40: =C35+C36+C37+C38+C39 -> 3872640 | D40: =D35+D36+D37+D38+D39 -> 3644650 | E40: =E35+E36+E37+E38+E39 -> 3449510 | F40: =SUMPRODUCT(C40:E40,C10:E10) -> 45852180 | G40: =IF($C$96=0,0,F40/$C$96) -> 3527090.8 | H40: =SUMPRODUCT(C40:E40,C10:E10,C25:E25) -> 550226160 | I40: 소계 + 연차 + 근로자의날 + 상여금 + 퇴직충당금
A41: 간접인건비 | B41: 건강보험료 | C41: =ROUNDUP((C40-C39-C33)*$C$73,-1) -> 128520 | D41: =ROUNDUP((D40-D39-D33)*$C$73,-1) -> 120950 | E41: =ROUNDUP((E40-E39-E33)*$C$73,-1) -> 114480 | F41: =SUMPRODUCT(C41:E41,C10:E10) -> 1521690 | G41: =IF($C$96=0,0,F41/$C$96) -> 117053.08 | H41: =SUMPRODUCT(C41:E41,C10:E10,C25:E25) -> 18260280 | I41: ROUNDUP((직접비 계 − 퇴직충당금 − 식대) × 건강보험요율, -1)
B42: 노인장기요양보험 | C42: =ROUNDUP(C41*$C$74,-1) -> 16890 | D42: =ROUNDUP(D41*$C$74,-1) -> 15900 | E42: =ROUNDUP(E41*$C$74,-1) -> 15050 | F42: =SUMPRODUCT(C42:E42,C10:E10) -> 200040 | G42: =IF($C$96=0,0,F42/$C$96) -> 15387.692 | H42: =SUMPRODUCT(C42:E42,C10:E10,C25:E25) -> 2400480 | I42: ROUNDUP(건강보험료 × 장기요양요율, -1)
B43: 국민연금 | C43: =ROUNDUP((C40-C39-C33)*$C$75*C22,-1) -> 178740 | D43: =ROUNDUP((D40-D39-D33)*$C$75*D22,-1) -> 168220 | E43: =ROUNDUP((E40-E39-E33)*$C$75*E22,-1) -> 159210 | F43: =SUMPRODUCT(C43:E43,C10:E10) -> 2116290 | G43: =IF($C$96=0,0,F43/$C$96) -> 162791.54 | H43: =SUMPRODUCT(C43:E43,C10:E10,C25:E25) -> 25395480 | I43: ROUNDUP((직접비−퇴직−식대) × 국민연금요율 × 적용률, -1)
B44: 고용보험료 | C44: =ROUNDUP((C40-C39-C33)*$C$76,-1) -> 66140 | D44: =ROUNDUP((D40-D39-D33)*$C$76,-1) -> 62240 | E44: =ROUNDUP((E40-E39-E33)*$C$76,-1) -> 58910 | F44: =SUMPRODUCT(C44:E44,C10:E10) -> 783050 | G44: =IF($C$96=0,0,F44/$C$96) -> 60234.615 | H44: =SUMPRODUCT(C44:E44,C10:E10,C25:E25) -> 9396600 | I44: ROUNDUP((직접비−퇴직−식대) × 고용보험요율, -1)
B45: 산재보험료 | C45: =ROUNDUP((C40-C39-C33)*$C$77,-1) -> 30750 | D45: =ROUNDUP((D40-D39-D33)*$C$77,-1) -> 28940 | E45: =ROUNDUP((E40-E39-E33)*$C$77,-1) -> 27390 | F45: =SUMPRODUCT(C45:E45,C10:E10) -> 364080 | G45: =IF($C$96=0,0,F45/$C$96) -> 28006.154 | H45: =SUMPRODUCT(C45:E45,C10:E10,C25:E25) -> 4368960 | I45: ROUNDUP((직접비−퇴직−식대) × 산재보험요율, -1)
...

Sheet 부대비용
B1: 부대비용 산출 명세 | E1: No. 261021-2703
E2: 작성일 2026. 10. 21
B3: 현대자동차 울산공장 정문 · 반영방식 인당 단가 균등 배분 · 단위: 원, VAT 별도
A7: 구분 | B7: 항목 | C7: 수량 | D7: 월 금액 | E7: 산출 근거
A8: 합계 | D8: 0 | E8: 인당 0원 배분 (13명)

Sheet 업무별 비용 배분
A1: 업무별 비용 배분 (견적서 기반) | X1: No. 261021-2703
X2: 작성일 2026. 10. 21
A3: 현대자동차 울산공장 정문 · 보안용역 도급업무 · 단위: 원, VAT 별도
A5: ■ 산정 요약 | N5: ■ 견적 금액 구성 (월)
A6: 산정 방식 | D6: B. 견적서 기반 업무별 비용 산정 | N6: 직접노무비 ① (산출내역서 40행) | Q6: 45852180 | R6: 0.8054
A7: 사업장 유형 · 직종 | D7: 공장 · 보안 | N7: 간접노무비 ② (산출내역서 50행) | Q7: 5634050 | R7: 0.099
A8: 견적 연도 | D8: 2027년 | N8: 경비 (산출내역서 61행) | Q8: 1728110 | R8: 0.0304
A9: 월 총 업무시간 (h) | D9: 1752.4397 | N9: 일반관리비 (산출내역서 63행) | Q9: 2660790 | R9: 0.0467
A10: 업무량 기준 필요 인원 (명) | D10: 10.7261 | N10: 기업이윤 · 단수조정 (65행 + 견적단가 1,000원 미만 절사) | Q10: 1052870 | R10: 0.0185
A11: 견적 인원 (명) | D11: 13 | N11: 월 합계 (= 견적서 월 합계) | Q11: =SUM(Q6:Q10) -> 56928000 | R11: 1
A12: 견적 인원 월 근무시간 (h) | D12: 2584.2167
A13: 1인 업무부하 (업무시간 ÷ 근무시간) | D13: 0.6781
A14: 견적 월 합계 (원) | D14: 56928000
A15: 계약기간 총액 (원) | D15: 683136000
A16: 시간당 단가 (월 합계 ÷ 월 업무시간) | D16: 32484.997
A17: 원 견적 인원 (명) | D17: 13
A18: 수행 가능 업무량 (원 견적 인원 기준) | D18: 1
A19: 부족 인력 (명) | D19: 0
A20: 부족 인력 반영 | D20: 해당 없음
A22: 코드 | B22: 대분류 | C22: 중분류 | D22: 업무명 | E22: 구분 | F22: 투입 | G22: 단위시간(분) | H22: 수량 | I22: 단위 | J22: 빈도 | K22: 주기 | L22: 월 횟수 | M22: 월 업무시간(h) | N22: 연 업무시간(h) | O22: 시간 비중 | P22: 시간당 단가 | Q22: 직접노무비 | R22: 간접노무비 | S22: 경비 | T22: 일반관리비 | U22: 이윤·단수 | V22: 월 배분액 | W22: 연 배분액 | X22: 단위당 단가
A23: A | B23: 출입통제 | E23: 19개 업무 | M23: 1009.0451 | N23: 12108.542 | O23: 0.5758 | P23: 32484.997 | Q23: 26401432 | R23: 3244055 | S23: 995035 | T23: 1532069 | U23: 606237 | V23: =SUM(Q23:U23) -> 32778828 | W23: =V23*12 -> 393345936 | Z23: 0
A24: A1 | B24: 출입통제 | C24: 정문 초소 | E24: 13개 업무 | M24: 729.6 | N24: 8755.2 | O24: 0.4163 | P24: 32484.996 | Q24: 19089815 | R24: 2345646 | S24: 719469 | T24: 1107777 | U24: 438346 | V24: =SUM(Q24:U24) -> 23701053 | W24: =V24*12 -> 284412636 | Z24: 0
A25: A1-1 | B25: 출입통제 | C25: 정문 초소 | D25: 정문 상주 근무 (24시간 경계·대기) | E25: 상주(잔여) | F25: 공통 | G25: 1440 | H25: 1 | I25: 개소 | J25: 1 | K25: 매일 | L25: 30.4 | M25: 427.7787 | N25: 5133.344 | O25: 0.2441 | P25: 32484.998 | Q25: 11192730 | R25: 1375298 | S25: 421840 | T25: 649511 | U25: 257010 | V25: =SUM(Q25:U25) -> 13896389 | W25: =V25*12 -> 166756668 | X25: 457118.06 | Z25: 1
A26: A1-2-a | B26: 출입통제 | C26: 정문 초소 | D26: 입문 차량 확인·출입 기록 | E26: 작업 | F26: 공통 | G26: 0.5 | H26: 108 | I26: 대 | J26: 1 | K26: 매일 | L26: 3283.2 | M26: 31.464 | N26: 377.568 | O26: 0.018 | P26: 32484.999 | Q26: 823248 | R26: 101156 | S26: 31027 | T26: 47773 | U26: 18904 | V26: =SUM(Q26:U26) -> 1022108 | W26: =V26*12 -> 12265296 | X26: 311.3146 | Z26: 1
A27: A1-2-b | B27: 출입통제 | C27: 정문 초소 | D27: 출문 차량 적재물 확인 | E27: 작업 | F27: 공통 | G27: 1 | H27: 54 | I27: 대 | J27: 1 | K27: 매일 | L27: 1641.6 | M27: 31.464 | N27: 377.568 | O27: 0.018 | P27: 32484.999 | Q27: 823248 | R27: 101156 | S27: 31027 | T27: 47773 | U27: 18904 | V27: =SUM(Q27:U27) -> 1022108 | W27: =V27*12 -> 12265296 | X27: 622.6291 | Z27: 1
A28: A1-2-c | B28: 출입통제 | C28: 정문 초소 | D28: 협력업체·납품차량 출입 통제 | E28: 작업 | F28: 공통 | G28: 3 | H28: 18 | I28: 대 | J28: 1 | K28: 매일 | L28: 547.2 | M28: 31.464 | N28: 377.568 | O28: 0.018 | P28: 32484.999 | Q28: 823248 | R28: 101156 | S28: 31027 | T28: 47773 | U28: 18904 | V28: =SUM(Q28:U28) -> 1022108 | W28: =V28*12 -> 12265296 | X28: 1867.8874 | Z28: 1
A29: A1-2-d | B29: 출입통제 | C29: 정문 초소 | D29: 긴급·관공서 차량 우선 통행 안내 | E29: 작업 | F29: 공통 | G29: 3 | H29: 2 | I29: 대 | J29: 1 | K29: 매일 | L29: 60.8 | M29: 3.496 | N29: 41.952 | O29: 0.002 | P29: 32484.84 | Q29: 91472 | R29: 11240 | S29: 3447 | T29: 5308 | U29: 2100 | V29: =SUM(Q29:U29) -> 113567 | W29: =V29*12 -> 1362804 | X29: 1867.8783 | Z29: 1
A30: A1-3-a | B30: 출입통제 | C30: 정문 초소 | D30: 방문객 신원확인·출입증 발급 | E30: 작업 | F30: 공통 | G30: 2 | H30: 60 | I30: 명 | J30: 1 | K30: 매일 | L30: 1824 | M30: 69.92 | N30: 839.04 | O30: 0.0399 | P30: 32484.997 | Q30: 1829441 | R30: 224791 | S30: 68949 | T30: 106162 | U30: 42008 | V30: =SUM(Q30:U30) -> 2271351 | W30: =V30*12 -> 27256212 | X30: 1245.2582 | Z30: 1
A31: A1-3-b | B31: 출입통제 | C31: 정문 초소 | D31: 출입증 회수·방문 대장 정리 | E31: 작업 | F31: 공통 | G31: 0.5 | H31: 60 | I31: 명 | J31: 1 | K31: 매일 | L31: 1824 | M31: 17.48 | N31: 209.76 | O31: 0.01 | P31: 32485.011 | Q31: 457360 | R31: 56198 | S31: 17237 | T31: 26541 | U31: 10502 | V31: =SUM(Q31:U31) -> 567838 | W31: =V31*12 -> 6814056 | X31: 311.3147 | Z31: 1
A32: A1-3-c | B32: 출입통제 | C32: 정문 초소 | D32: 사전 방문예약 확인·접견자 연락 | E32: 작업 | F32: 공통 | G32: 1 | H32: 24 | I32: 건 | J32: 1 | K32: 매일 | L32: 729.6 | M32: 13.984 | N32: 167.808 | O32: 0.008 | P32: 32484.983 | Q32: 365888 | R32: 44958 | S32: 13790 | T32: 21232 | U32: 8402 | V32: =SUM(Q32:U32) -> 454270 | W32: =V32*12 -> 5451240 | X32: 622.6288 | Z32: 1
A33: A1-4-a | B33: 출입통제 | C33: 정문 초소 | D33: 반출입증 확인·물품 대조 | E33: 작업 | F33: 공통 | G33: 3 | H33: 14 | I33: 건 | J33: 1 | K33: 매일 | L33: 425.6 | M33: 24.472 | N33: 293.664 | O33: 0.014 | P33: 32485.003 | Q33: 640304 | R33: 78677 | S33: 24132 | T33: 37157 | U33: 14703 | V33: =SUM(Q33:U33) -> 794973 | W33: =V33*12 -> 9539676 | X33: 1867.8877 | Z33: 1
A34: A1-4-b | B34: 출입통제 | C34: 정문 초소 | D34: 반입 금지물품(화기·위험물) 검색 | E34: 작업 | F34: 공통 | G34: 1 | H34: 60 | I34: 명 | J34: 1 | K34: 매일 | L34: 1824 | M34: 34.96 | N34: 419.52 | O34: 0.0199 | P34: 32484.983 | Q34: 914720 | R34: 112395 | S34: 34475 | T34: 53081 | U34: 21004 | V34: =SUM(Q34:U34) -> 1135675 | W34: =V34*12 -> 13628100 | X34: 622.6288 | Z34: 1
A35: A1-5-a | B35: 출입통제 | C35: 정문 초소 | D35: 택배 수령·보관 등록 | E35: 작업 | F35: 공통 | G35: 1 | H35: 40 | I35: 건 | J35: 1 | K35: 매일 | L35: 1216 | M35: 23.3067 | N35: 279.68 | O35: 0.0133 | P35: 32484.997 | Q35: 609814 | R35: 74930 | S35: 22983 | T35: 35387 | U35: 14003 | V35: =SUM(Q35:U35) -> 757117 | W35: =V35*12 -> 9085404 | X35: 622.6291 | Z35: 1
A36: A1-5-b | B36: 출입통제 | C36: 정문 초소 | D36: 수령자 연락·인계 확인 | E36: 작업 | F36: 공통 | G36: 0.7 | H36: 40 | I36: 건 | J36: 1 | K36: 매일 | L36: 1216 | M36: 16.3147 | N36: 195.776 | O36: 0.0093 | P36: 32485.003 | Q36: 426870 | R36: 52451 | S36: 16088 | T36: 24771 | U36: 9802 | V36: =SUM(Q36:U36) -> 529982 | W36: =V36*12 -> 6359784 | X36: 435.8405 | Z36: 1
A37: A1-5-c | B37: 출입통제 | C37: 정문 초소 | D37: 등기·우편물 분류 | E37: 작업 | F37: 공통 | G37: 0.5 | H37: 12 | I37: 건 | J37: 1 | K37: 매일 | L37: 364.8 | M37: 3.496 | N37: 41.952 | O37: 0.002 | P37: 32484.84 | Q37: 91472 | R37: 11240 | S37: 3447 | T37: 5308 | U37: 2100 | V37: =SUM(Q37:U37) -> 113567 | W37: =V37*12 -> 1362804 | X37: 311.313 | Z37: 1
A38: A2 | B38: 출입통제 | C38: 후문·부출입구 | E38: 3개 업무 | M38: 260.7143 | N38: 3128.5714 | O38: 0.1488 | P38: 32484.994 | Q38: 6821529 | R38: 838189 | S38: 257095 | T38: 395852 | U38: 156637 | V38: =SUM(Q38:U38) -> 8469302 | W38: =V38*12 -> 101631624 | Z38: 0
A39: A2-1 | B39: 출입통제 | C39: 후문·부출입구 | D39: 후문 주간 상주 (07~19시) | E39: 상주(잔여) | F39: 공통 | G39: 720 | H39: 1 | I39: 개소 | J39: 5 | K39: 매주 | L39: 21.7262 | M39: 224.0758 | N39: 2688.91 | O39: 0.1279 | P39: 32484.994 | Q39: 5862892 | R39: 720398 | S39: 220965 | T39: 340222 | U39: 134625 | V39: =SUM(Q39:U39) -> 7279102 | W39: =V39*12 -> 87349224 | X39: 335038.12 | Z39: 1
A40: A2-2 | B40: 출입통제 | C40: 후문·부출입구 | D40: 출퇴근 시간 출입 통제 | E40: 작업 | F40: 공통 | G40: 30 | H40: 1 | I40: 개소 | J40: 10 | K40: 매주 | L40: 43.4524 | M40: 24.9851 | N40: 299.8214 | O40: 0.0143 | P40: 32484.976 | Q40: 653730 | R40: 80326 | S40: 24638 | T40: 37936 | U40: 15011 | V40: =SUM(Q40:U40) -> 811641 | W40: =V40*12 -> 9739692 | X40: 18678.861 | Z40: 1
A41: A2-3 | B41: 출입통제 | C41: 후문·부출입구 | D41: 야간 출입문 시건·개방 | E41: 작업 | F41: 공통 | G41: 10 | H41: 1 | I41: 개소 | J41: 2 | K41: 매일 | L41: 60.8 | M41: 11.6533 | N41: 139.84 | O41: 0.0066 | P41: 32485.04 | Q41: 304907 | R41: 37465 | S41: 11492 | T41: 17694 | U41: 7001 | V41: =SUM(Q41:U41) -> 378559 | W41: =V41*12 -> 4542708 | X41: 6226.2993 | Z41: 1
A42: A3 | B42: 출입통제 | C42: 출입보안시스템 | E42: 3개 업무 | M42: 18.7309 | N42: 224.7702 | O42: 0.0107 | P42: 32485.066 | Q42: 490088 | R42: 60220 | S42: 18471 | T42: 28440 | U42: 11254 | V42: =SUM(Q42:U42) -> 608473 | W42: =V42*12 -> 7301676 | Z42: 0
...

Sheet 업무량 산출내역
B1: 현대자동차 울산공장 정문 보안용역 도급업무 업무량 산출내역 (Workload) | R1: No. 261021-2703
B2: Location: 현대자동차 울산공장 정문 · 울산 북구 염포로 700 | R2: 작성일 2026. 10. 21
B3: 2027년 · 평일: 246일 / 주말: 104일 / 공휴일: 15일 · 주간 06~22시 · 야간 22~06시
B5: 도급 업무 (분류별 세부업무) | C5: 시간당 단가 | D5: Work scope (시간) | K5: Amount (노무비, 원) | R5: 비고
D6: TOTAL | E6: 주중 주간 | F6: 주중 야간 | G6: 주말 주간 | H6: 주말 야간 | I6: 공휴일 주간 | J6: 공휴일 야간 | K6: TOTAL | L6: 주중 주간 | M6: 주중 야간 | N6: 주말 주간 | O6: 주말 야간 | P6: 공휴일 주간 | Q6: 공휴일 야간
B7: A 출입통제 | C7: 29379.743 | D7: =SUM(E7:J7) -> 12108.542 | E7: 7806.2826 | F7: 1247.4927 | G7: 2142.3164 | H7: 527.3953 | I7: 308.9879 | J7: 76.0666 | K7: =SUM(L7:Q7) -> 355745844 | L7: 229346575 | M7: 36651018 | N7: 62940707 | O7: 15494740 | P7: 9077986 | Q7: 2234818 | T7: 0
B8: A1 정문 초소 | C8: 29379.744 | D8: =SUM(E8:J8) -> 8755.2 | E8: 4747.5205 | F8: 1153.2444 | G8: 2007.0818 | H8: 487.5505 | I8: 289.483 | J8: 70.3198 | K8: =SUM(L8:Q8) -> 257225532 | L8: 139480935 | M8: 33882026 | N8: 58967551 | O8: 14324109 | P8: 8504934 | Q8: 2065977 | T8: 0
B9: A1-1 정문 상주 근무 (24시간 경계·대기) | C9: 29379.745 | D9: =SUM(E9:J9) -> 5133.344 | E9: 2306.4888 | F9: 1153.2444 | G9: 975.101 | H9: 487.5505 | I9: 140.6396 | J9: 70.3198 | K9: =SUM(L9:Q9) -> 150816336 | L9: 67764052 | M9: 33882026 | N9: 28648217 | O9: 14324109 | P9: 4131955 | Q9: 2065977 | R9: 상주 시간 중 다른 업무를 뺀 경계·대기 | T9: 1
B10: A1-2-a 입문 차량 확인·출입 기록 | C10: 29379.736 | D10: =SUM(E10:J10) -> 377.568 | E10: 254.4705 | F10: 0 | G10: 107.581 | H10: 0 | I10: 15.5165 | J10: 0 | K10: =SUM(L10:Q10) -> 11092848 | L10: 7476276 | M10: 0 | N10: 3160702 | O10: 0 | P10: 455870 | Q10: 0 | T10: 1
B11: A1-2-b 출문 차량 적재물 확인 | C11: 29379.736 | D11: =SUM(E11:J11) -> 377.568 | E11: 254.4705 | F11: 0 | G11: 107.581 | H11: 0 | I11: 15.5165 | J11: 0 | K11: =SUM(L11:Q11) -> 11092848 | L11: 7476276 | M11: 0 | N11: 3160702 | O11: 0 | P11: 455870 | Q11: 0 | T11: 1
B12: A1-2-c 협력업체·납품차량 출입 통제 | C12: 29379.736 | D12: =SUM(E12:J12) -> 377.568 | E12: 254.4705 | F12: 0 | G12: 107.581 | H12: 0 | I12: 15.5165 | J12: 0 | K12: =SUM(L12:Q12) -> 11092848 | L12: 7476276 | M12: 0 | N12: 3160702 | O12: 0 | P12: 455870 | Q12: 0 | T12: 1
B13: A1-2-d 긴급·관공서 차량 우선 통행 안내 | C13: 29379.863 | D13: =SUM(E13:J13) -> 41.952 | E13: 28.2745 | F13: 0 | G13: 11.9534 | H13: 0 | I13: 1.7241 | J13: 0 | K13: =SUM(L13:Q13) -> 1232544 | L13: 830701 | M13: 0 | N13: 351191 | O13: 0 | P13: 50652 | Q13: 0 | T13: 1
B14: A1-3-a 방문객 신원확인·출입증 발급 | C14: 29379.748 | D14: =SUM(E14:J14) -> 839.04 | E14: 565.49 | F14: 0 | G14: 239.0689 | H14: 0 | I14: 34.4811 | J14: 0 | K14: =SUM(L14:Q14) -> 24650784 | L14: 16613953 | M14: 0 | N14: 7023785 | O14: 0 | P14: 1013046 | Q14: 0 | T14: 1
B15: A1-3-b 출입증 회수·방문 대장 정리 | C15: 29379.748 | D15: =SUM(E15:J15) -> 209.76 | E15: 141.3725 | F15: 0 | G15: 59.7672 | H15: 0 | I15: 8.6203 | J15: 0 | K15: =SUM(L15:Q15) -> 6162696 | L15: 4153488 | M15: 0 | N15: 1755946 | O15: 0 | P15: 253262 | Q15: 0 | T15: 1
B16: A1-3-c 사전 방문예약 확인·접견자 연락 | C16: 29379.72 | D16: =SUM(E16:J16) -> 167.808 | E16: 113.098 | F16: 0 | G16: 47.8138 | H16: 0 | I16: 6.8962 | J16: 0 | K16: =SUM(L16:Q16) -> 4930152 | L16: 3322787 | M16: 0 | N16: 1404756 | O16: 0 | P16: 202609 | Q16: 0 | T16: 1
B17: A1-4-a 반출입증 확인·물품 대조 | C17: 29379.74 | D17: =SUM(E17:J17) -> 293.664 | E17: 197.9215 | F17: 0 | G17: 83.6741 | H17: 0 | I17: 12.0684 | J17: 0 | K17: =SUM(L17:Q17) -> 8627772 | L17: 5814882 | M17: 0 | N17: 2458324 | O17: 0 | P17: 354566 | Q17: 0 | T17: 1
B18: A1-4-b 반입 금지물품(화기·위험물) 검색 | C18: 29379.72 | D18: =SUM(E18:J18) -> 419.52 | E18: 282.745 | F18: 0 | G18: 119.5345 | H18: 0 | I18: 17.2405 | J18: 0 | K18: =SUM(L18:Q18) -> 12325380 | L18: 8306968 | M18: 0 | N18: 3511889 | O18: 0 | P18: 506523 | Q18: 0 | T18: 1
B19: A1-5-a 택배 수령·보관 등록 | C19: 29379.748 | D19: =SUM(E19:J19) -> 279.68 | E19: 188.4967 | F19: 0 | G19: 79.6896 | H19: 0 | I19: 11.4937 | J19: 0 | K19: =SUM(L19:Q19) -> 8216928 | L19: 5537984 | M19: 0 | N19: 2341262 | O19: 0 | P19: 337682 | Q19: 0 | T19: 1
B20: A1-5-b 수령자 연락·인계 확인 | C20: 29379.761 | D20: =SUM(E20:J20) -> 195.776 | E20: 131.9477 | F20: 0 | G20: 55.7828 | H20: 0 | I20: 8.0456 | J20: 0 | K20: =SUM(L20:Q20) -> 5751852 | L20: 3876591 | M20: 0 | N20: 1638884 | O20: 0 | P20: 236377 | Q20: 0 | T20: 1
B21: A1-5-c 등기·우편물 분류 | C21: 29379.863 | D21: =SUM(E21:J21) -> 41.952 | E21: 28.2745 | F21: 0 | G21: 11.9534 | H21: 0 | I21: 1.7241 | J21: 0 | K21: =SUM(L21:Q21) -> 1232544 | L21: 830701 | M21: 0 | N21: 351191 | O21: 0 | P21: 50652 | Q21: 0 | T21: 1
B22: A2 후문·부출입구 | C22: 29379.74 | D22: =SUM(E22:J22) -> 3128.5714 | E22: 2890.9814 | F22: 94.2483 | G22: 85.4286 | H22: 39.8448 | I22: 12.3214 | J22: 5.7468 | K22: =SUM(L22:Q22) -> 91916616 | L22: 84936284 | M22: 2768992 | N22: 2509868 | O22: 1170631 | P22: 362000 | Q22: 168841 | T22: 0
B23: A2-1 후문 주간 상주 (07~19시) | C23: 29379.741 | D23: =SUM(E23:J23) -> 2688.91 | E23: 2688.91 | F23: 0 | G23: 0 | H23: 0 | I23: 0 | J23: 0 | K23: =SUM(L23:Q23) -> 78999480 | L23: 78999480 | M23: 0 | N23: 0 | O23: 0 | P23: 0 | Q23: 0 | R23: 상주 시간 중 다른 업무를 뺀 경계·대기 | T23: 1
B24: A2-2 출퇴근 시간 출입 통제 | C24: 29379.728 | D24: =SUM(E24:J24) -> 299.8214 | E24: 202.0714 | F24: 0 | G24: 85.4286 | H24: 0 | I24: 12.3214 | J24: 0 | K24: =SUM(L24:Q24) -> 8808672 | L24: 5936804 | M24: 0 | N24: 2509868 | O24: 0 | P24: 362000 | Q24: 0 | T24: 1
B25: A2-3 야간 출입문 시건·개방 | C25: 29379.748 | D25: =SUM(E25:J25) -> 139.84 | E25: 0 | F25: 94.2483 | G25: 0 | H25: 39.8448 | I25: 0 | J25: 5.7468 | K25: =SUM(L25:Q25) -> 4108464 | L25: 0 | M25: 2768992 | N25: 0 | O25: 1170631 | P25: 0 | Q25: 168841 | T25: 1
B26: A3 출입보안시스템 | C26: 29379.762 | D26: =SUM(E26:J26) -> 224.7702 | E26: 167.7806 | F26: 0 | G26: 49.806 | H26: 0 | I26: 7.1836 | J26: 0 | K26: =SUM(L26:Q26) -> 6603696 | L26: 4929356 | M26: 0 | N26: 1463288 | O26: 0 | P26: 211052 | Q26: 0 | T26: 0
B27: A3-1 출입카드 발급·회수·분실 처리 | C27: 29379.808 | D27: =SUM(E27:J27) -> 49.9702 | E27: 49.9702 | F27: 0 | G27: 0 | H27: 0 | I27: 0 | J27: 0 | K27: =SUM(L27:Q27) -> 1468116 | L27: 1468116 | M27: 0 | N27: 0 | O27: 0 | P27: 0 | Q27: 0 | T27: 1
B28: A3-2 출입기록 확인·이상 출입 조치 | C28: 29379.748 | D28: =SUM(E28:J28) -> 104.88 | E28: 70.6862 | F28: 0 | G28: 29.8836 | H28: 0 | I28: 4.3101 | J28: 0 | K28: =SUM(L28:Q28) -> 3081348 | L28: 2076744 | M28: 0 | N28: 877973 | O28: 0 | P28: 126631 | Q28: 0 | T28: 1
B29: A3-3 스피드게이트·출입통제기 작동 확인 | C29: 29379.748 | D29: =SUM(E29:J29) -> 69.92 | E29: 47.1242 | F29: 0 | G29: 19.9224 | H29: 0 | I29: 2.8734 | J29: 0 | K29: =SUM(L29:Q29) -> 2054232 | L29: 1384496 | M29: 0 | N29: 585315 | O29: 0 | P29: 84421 | Q29: 0 | T29: 1
B30: B 순찰 | C30: 29379.743 | D30: =SUM(E30:J30) -> 5015.472 | E30: 3242.7989 | F30: 254.4705 | G30: 1219.2516 | H30: 107.581 | I30: 175.8536 | J30: 15.5165 | K30: =SUM(L30:Q30) -> 147353280 | L30: 95272599 | M30: 7476276 | N30: 35821299 | O30: 3160702 | P30: 5166534 | Q30: 455870 | T30: 0
B31: B1 정기순찰 | C31: 29379.743 | D31: =SUM(E31:J31) -> 3817.632 | E31: 2318.5089 | F31: 254.4705 | G31: 980.1826 | H31: 107.581 | I31: 141.3725 | J31: 15.5165 | K31: =SUM(L31:Q31) -> 112161048 | L31: 68117198 | M31: 7476276 | N31: 28797514 | O31: 3160702 | P31: 4153488 | Q31: 455870 | T31: 0
B32: B1-1 외곽 울타리·담장 순찰 | C32: 29379.741 | D32: =SUM(E32:J32) -> 1678.08 | E32: 1130.9799 | F32: 0 | G32: 478.1379 | H32: 0 | I32: 68.9622 | J32: 0 | K32: =SUM(L32:Q32) -> 49301556 | L32: 33227898 | M32: 0 | N32: 14047567 | O32: 0 | P32: 2026091 | Q32: 0 | T32: 1
B33: B1-2 건물 내부 층별 순찰 | C33: 29379.748 | D33: =SUM(E33:J33) -> 1258.56 | E33: 848.235 | F33: 0 | G33: 358.6034 | H33: 0 | I33: 51.7216 | J33: 0 | K33: =SUM(L33:Q33) -> 36976176 | L33: 24920930 | M33: 0 | N33: 10535677 | O33: 0 | P33: 1519569 | Q33: 0 | T33: 1
B34: B1-3 주차장 순찰 | C34: 29379.744 | D34: =SUM(E34:J34) -> 503.424 | E34: 339.294 | F34: 0 | G34: 143.4414 | H34: 0 | I34: 20.6887 | J34: 0 | K34: =SUM(L34:Q34) -> 14790468 | L34: 9968370 | M34: 0 | N34: 4214270 | O34: 0 | P34: 607828 | Q34: 0 | T34: 1
B35: B1-4 야간 문단속·소등·전열기구 확인 | C35: 29379.736 | D35: =SUM(E35:J35) -> 377.568 | E35: 0 | F35: 254.4705 | G35: 0 | H35: 107.581 | I35: 0 | J35: 15.5165 | K35: =SUM(L35:Q35) -> 11092848 | L35: 0 | M35: 7476276 | N35: 0 | O35: 3160702 | P35: 0 | Q35: 455870 | T35: 1
... B103: F4 경비원 직무교육·소방훈련 참여 | C103: 29379.783 | D103: =SUM(E103:J103) -> 18.4 | E103: 18.4 | F103: 0 | G103: 0 | H103: 0 | I103: 0 | J103: 0 | K103: =SUM(L103:Q103) -> 540588 | L103: 540588 | M103: 0 | N103: 0 | O103: 0 | P103: 0 | Q103: 0 | T103: 1
B104: 소 계 (노무비) | C104: 29379.744 | D104: =SUMIF($T$7:$T$103,1,D7:D103) -> 21029.277 | E104: =SUMIF($T$7:$T$103,1,E7:E103) -> 14076.705 | F104: =SUMIF($T$7:$T$103,1,F7:F103) -> 1501.9632 | G104: =SUMIF($T$7:$T$103,1,G7:G103) -> 4128.5808 | H104: =SUMIF($T$7:$T$103,1,H7:H103) -> 634.9763 | I104: =SUMIF($T$7:$T$103,1,I7:I103) -> 595.4684 | J104: =SUMIF($T$7:$T$103,1,J7:J103) -> 91.5831 | K104: =SUMIF($T$7:$T$103,1,K7:K103) -> 617834760 | ... Q104: =SUMIF($T$7:$T$103,1,Q7:Q103) -> 2690688
B105: 경비 (피복·복리후생·교육·위험부담 등) | K105: 20737320
B106: 일반관리비 | K106: 31929480
B107: 기업이윤 · 단수조정 | K107: 12634440
B108: 도급비 합계 (연 · VAT 별도) | K108: =SUM(K104:K107) -> 683136000 | R108: = 견적서 계약기간 총액
...

Sheet _stec_data
A1: {"meta":{"client":"현대자동차 울산공장 정문","addr":"울산 북구 염포로 700","svc":"보안용역 도급업무","year":2027,"date":"2026-10-21","from":"2027-01-01","to":"2027-12-31","valid":"작성일로부터 1개월","mode":"new","branch":"부경본부","grpCo":"에스텍시스템","siteId":null,"lat":35.54323224110387,"lng":129.38463055208857,"geoName":"현대자동차 울산공장 정문","geoSrc":"카카오맵","geoInfo":{"src":"카카오맵","name":"현대자동차 울산공장 정문","type":"입출구","addr":"울산 북구 염포로 700","region":"울산 북구 양정동","postcode":"","osm":"","lat":35.54323224110387,"lng":129.38463055208857,"tags":{},"wiki":{"title":"정주영","extract":"정주영(鄭周永, 1915년 11월 25일~2001년 3월 21일)은 현대그룹 창업주로 대한민국의 기업인, 정치인이다. 제14대 국회의원을 지냈다. 본관은 하동(河東), 아호(雅號)는 아산(峨山)이다.","url":"https://ko.wikipedia.org/wiki/%EC%A0%95%EC%A3%BC%EC%98%81","thumb":"https://thumb.wikimedia.org/wikipedia/commons/thumb/c/c3/Chung_Ju-yung_%28Cropped%29.jpg/330px-Chung_Ju-yung_%28Cropped%29.jpg?utm_source=ko.wikipedia.org&utm_campaign=api&utm_content=thumbnail"},"loading":false,"category":"교통,수송 > 입출구","road":"울산 북구 염포로 700","jibun":"울산 북구 양정동 700","phone":"","kakaoUrl":"http://place.map.kakao.com/394445757","kid":"394445757"}},"roles":[{"id":"r1000ibzc","cat":"sec","rank":"실장","detail":"","gender":"M","shift":"day5_11","count":1,"wage":10700,"base":209,"ot":65,"night":0,"dayH":12,"rest":1,"watch":true,"pos":0,"adj":0,"duty":500000,"meal":0,"holDays":0,"leave":15,"laborDay":true,"retire":true,"bonusPct":0,"bonusBase":"basic","pensionPct":100,"special":"auto","uniform":30000,"months":12,"prev":0,"note":"","addonEx":false,"title":"실장"},{"id":"r1001vcmk","cat":"sec","rank":"팀장","detail":"","gender":"M","shift":"day5_11","count":3,"wage":10700,"base":209,"ot":65,"night":0,"dayH":12,"rest":1,"watch":true,"pos":0,"adj":0,"duty":300000,"meal":0,"holDays":0,"leave":15,"laborDay":true,"retire":true,"bonusPct":0,"bonusBase":"basic","pensionPct":100,"special":"auto","uniform":30000,"months":12,"prev":0,"note":"","addonEx":false,"title":"팀장"},{"id":"r1002p9ns","cat":"sec","rank":"요원","detail":"","gender":"M","shift":"s32","count":9,"wage":10700,"base":209,"ot":25,"night":82,"dayH":12,"rest":1,"watch":true,"pos":0,"adj":100000,"duty":0,"meal":0,"holDays":0,"leave":15,"laborDay":true,"retire":true,"bonusPct":0,"bonusBase":"basic","pensionPct":100,"special":"auto","uniform":30000,"months":12,"prev":0,"note":"","addonEx":false,"title":"요원"}],"vehicles":[],"equips":[],"others":[],"addonMode":"spread","addonMargin":true,"set":{"minWage":10700,"health":3.595,"ltc":13.14,"pension":5,"empSize":"o1000","emp":1.85,"indBase":0.8,"indCom":0.06,"ind":0.86,"wageClaim":0.09,"asb":0.006,"otGen":1.5,"otWatch":1,"nightRate":0.5,"specialExam":80000,"disOn":true,"disRate":3.1,"disBase":1360000,"disRatio":100,"gift":100000,"meeting":10000,"condol":4000,"reliefH":12,"reliefDays":1.8,"resTax":62500,"resSites":1,"edu":1,"eduFix":0,"risk":0.5,"riskFix":0,"leaveH":8,"ga":5,"profit":2,"profitBase":"direct","gaRound":true,"priceRound":"down3","vat":10,"coKey":"에스텍시스템","coName":"㈜에스텍시스템","coCeo":"이병화","coBizNo":"202-81-62708","coCorpNo":"110111-1627144","coAddr":"서울특별시 강남구 개포로 619, 8층(개포동, 서울강남우체국청사)","coType":"서비스","coItem":"시설경비·신변보호·기계경비·호송경비, 건물(시설)관리용역, 위생관리, 주차관리","coLic":"","coBranch":"에스텍 그룹","coPerson":"","coPersonTitle":"","coPersonTel":"","cond":"○ 견적 기준 : {연도}년 최저임금({최저시급}원) 및 통상시급 적용\n 단, 매년 법정최저임금(4대보험 포함) 등 관계법령이 변경될 경우 그 즉시 변경된 내용에 따라 적용합니다.\n○ 납입 조건 : 전자세금계산서 발행(당월 20일 청구, 익월 5일 납입, 현금결제)\n○ 손해배상 : 총 2억원 (당사의 귀책사유로 인한 사고 발생시 손해배상 책임보험에 의거)\n 1) 대인배상 : 1인 2천만원 한도 총 1억원(1사고당), 2) 대물배상 : 1억원한도(사고당)\n○ 상기 금액은 피복, 장비, 복리후생 등 포함한 금액입니다.\n○ 업무 수행에 필요한 근무실, 휴게실, 청소용품(소모품 포함), 집기류, 통신, 식사는 고객사 제공조건"},"wbe":{"v":"1.6","mode":"B","ind":"factory","job":"sec","year":2027,"H":1752.4,"add":0,"tree":[{"id":"n27","name":"출입통제","kids":[{"id":"n18","name":"정문 초소","kids":[{"id":"n1","name":"정문 상주 근무 (24시간 경계·대기)","kids":[],"t":{"min":1440,"qty":1,"unit":"개소","freq":1,"per":"d","type":"post","g":"C","pick":true}},{"id":"n6","name":"차량 출입관리","kids":[{"id":"n2","name":"입문 차량 확인·출입 기록","kids":[],"t":{"min":0.5,"qty":108,"unit":"대","freq":1,"per":"d","type":"work","g":"C","pick":true}},{"id":"n3","name":"출문 차량 적재물 확인","kids":[],"t":{"min":1,"qty":54,"unit":"대","freq":1,"per":"d","type":"work","g":"C","pick":true}},{"id":"n4","name":"협력업체·납품차량 출입 통제","kids":[],"t":{"min":3,"qty":18,"unit":"대","freq":1,"per":"d","type":"work","g":"C","pick":true}},{"id":"n5","name":"긴급·관공서 차량 우선 통행 안내","kids":[],"t":{"min":3,"qty":2,"unit":"대","freq":1,"per":"d","type":"work","g":"C","pick":true}}],"t":{"min":0,"qty":1,"unit":"회","freq":1,"per":"d","type":"work","g":"C"}},{"id":"n10","name":"방문객 관리","kids":[{"id":"n7","name":"방문객 신원확인·출입증 발급","kids":[],"t":{"min":2,"qty":60,"unit":"명","freq":1,"per":"d","type":"work","g":"C","pick":true}},{"id":"n8","name":"출입증 회수·방문 대장 정리","kids":[],"t":{"min":0.5,"qty":60,"unit":"명","freq":1,"per":"d","type":"work","g":"C","pick":true}},{"id":"n9","name":"사전 방문예약 확인·접견자 연락","kids":[],"t":{"min":1,"qty":24,"unit":"건","freq":1,"per":"d","type":"work","g":"C","pick":true}}],"t":{"min":0,"qty":1,"unit":"회","freq":1,"per":"d","type":"work","g":"C"}},{"id":"n13","name":"물품 반출입 관리","kids":[{"id":"n11","name":"반출입증 확인·물품 대조","kids":[],"t":{"min":3,"qty":14,"unit":"건","freq":1,"per":"d","type":"work","g":"C","pick":true}},{"id":"n12","name":"반입 금지물품(화기·위험물) 검색","kids":[],"t":{"min":1,"qty":60,"unit":"명","freq":1,"per":"d","type":"work","g":"C","pick":true}}],"t":{"min":0,"qty":1,"unit":"회","freq":1,"per":"d","type":"work","g":"C"}},{"id":"n17","name":"택배·우편 관리","kids":[{"id":"n14","name":"택배 수령·보관 등록","kids":[],"t":{"min":1,"qty":40,"unit":"건","freq":1,"per":"d","type":"work","g":"C","pick":true}},{"id":"n15","name":"수령자 연락·인계 확인","kids":[],"t":{"min":0.7,"qty":40,"unit":"건","freq":1,"per":"d","type":"work","g":"C","pick":true}},{"id":"n16","name":"등기·우편물 분류","kids":[],"t":{"min":0.5,"qty":12,"unit":"건","freq":1,"per":"d","type":"work","g":"C","pick":true}}],"t":{"min":0,"qty":1,"unit":"회","freq":1,"per":"d","type":"work","g":"C"}}],"t":{"min":0,"qty":1,"unit":"회","freq":1,"per":"d","type":"work","g":"C"}},{"id":"n22","name":"후문·부출입구","kids":[{"id":"n19","name":"후문 주간 상주 (07~19시)","kids":[],"t":{"min":720,"qty":1,"unit":"개소","freq":5,"per":"w","type":"post","g":"C","pick":true}},{"id":"n20","name":"출퇴근 시간 출입 통제","kids":[],"t":{"min":30,"qty":1,"unit":"개소","freq":10,"per":"w","type":"work","g":"C","pick":true}},{"id":"n21","name":"야간 출입문 시건·개방","kids":[],"t":{"min":10,"qty":1,"unit":"개소","freq":2,"per":"d","type":"work","g":"C","pick":true}}],"t":{"min":0,"qty":1,"unit":"회","freq":1,"per":"d","type":"work","g":"C"}},{"id":"n26","name":"출입보안시스템","kids":[{"id":"n23","name":"출입카드 발급·회수·분실 처리","kids":[],"t":{"min":5,"qty":10,"unit":"건","freq":1,"per":"w","type":"work","g":"C","pick":true}},{"id":"n24","name":"출입기록 확인·이상 출입 조치","kids":[],"t":{"min":15,"qty":1,"unit":"회","freq":1,"per":"d","type":"work","g":"C","pick":true}},{"id":"n25","name":"스피드게이트·출입통제기 작동 확인","kids":[],"t":{"min":5,"qty":2,"unit":"대","freq":1,"per":"d","type":"work","g":"C","pick":true}}],"t":{"min":0,"qty":1,"unit":"회","freq":1,"per":"d","type":"work","g":"C"}}],"t":{"min":0,"qty":1,"unit":"회","freq":1,"per":"d","type":"work","g":"C"}},{"id":"n37","name":"순찰","kids":[{"id":"n32","name":"정기순찰","kids":[{"id":"n28","name":"외곽 울타리·담장 순찰","kids":[],"t":{"min":30,"qty":2,"unit":"구역","freq":4,"per":"d","type":"work","g":"C","pick":true}},{"id":"n29","name":"건물 내부 층별 순찰","kids":[],"t":{"min":5,"qty":18,"unit":"층","freq":2,"per":"d","type":"work","g":"C","pick":true}},{"id":"n30","name":"주차장 순찰","kids":[],"t":{"min":8,"qty":3,"unit":"구역","freq":3,"per":"d","type":"work","g":"C","pick":true}},{"id":"n31","name":"야간 문단속·소등·전열기구 확인","kids":[],"t":{"min":3,"qty":18,"unit":"층","freq":1,"per":"d","type":"work","g":"C","pick":true}}],"t":{"min":0,"qty":1,"unit":"회","freq":1,"per":"d","type":"work","g":"C"}},{"id":"n36","name":"특별순찰","kids":[{"id":"n33","name":"취약지역·사각지대 집중 순찰","kids":[],"t":{"min":20,"qty":3,"unit":"개소","freq":2,"per":"d","type":"work","g":"C","pick":true}},{"id":"n34","name":"휴일·공휴일 전수 점검","kids":[],"t":{"min":30,"qty":6,"unit":"동","freq":8,"per":"m","type":"work","g":"C","pick":true}},{"id":"n35","name":"기상특보(태풍·폭우·폭설) 비상 순찰","kids":[],"t":{"min":60,"qty":6,"unit":"동","freq":4,"per":"y","type":"work","g":"C","pick":true}}],"t":{"min":0,"qty":1,"unit":"회","freq":1,"per":"d","type":"work","g":"C"}}],"t":{"min":0,"qty":1,"unit":"회","freq":1,"per":"d","type":"work","g":"C"}},{"id":"n67","name":"상황대처","kids":[{"id":"n42","name":"화재·소방","kids":[{"id":"n38","name":"화재경보 발생 시 현장 출동·확인","kids":[],"t":{"min":15,"qty":1,"unit":"건","freq":6,"per":"m","type":"work","g":"C","pick":true}},{"id":"n39","name":"비화재보 복구·수신기 리셋","kids":[],"t":{"min":10,"qty":1,"unit":"건","freq":4,"per":"m","type":"work","g":"C","pick":true}},{"id":"n40","name":"초기 소화·피난 유도","kids":[],"t":{"min":60,"qty":1,"unit":"건","freq":1,"per":"y","type":"work","g":"C","pick":true}},{"id":"n41","name":"소방서 신고·소방차 진입 안내","kids":[],"t":{"min":20,"qty":1,"unit":"건","freq":1,"per":"q","type":"work","g":"C","pick":true}}],"t":{"min":0,"qty":1,"unit":"회","freq":1,"per":"d","type":"work","g":"C"}},{"id":"n48","name":"응급·안전사고","kids":[{"id":"n43","name":"응급환자 응급조치·119 신고·인계","kids":[],"t":{"min":30,"qty":1,"unit":"건","freq":1,"per":"m","type":"work","g":"C","pick":true}},{"id":"n44","name":"AED·구급함 점검","kids":[],"t":{"min":5,"qty":6,"unit":"개소","freq":1,"per":"m","type":"work","g":"C","pick":true}},{"id":"n45","name":"산업재해 발생 시 현장 통제·보고","kids":[],"t":{"min":60,"qty":1,"unit":"건","freq":2,"per":"y","type":"work","g":"C","pick":true}},{"id":"n46","name":"승강기 갇힘 사고 대응·구조 연계","kids":[],"t":{"min":30,"qty":1,"unit":"건","freq":1,"per":"m","type":"work","g":"C","pick":true}},{"id":"n47","name":"넘어짐·추락 사고 현장 조치","kids":[],"t":{"min":20,"qty":1,"unit":"건","freq":1,"per":"m","type":"work","g":"C","pick":true}}],"t":{"min":0,"qty":1,"unit":"회","freq":1,"per":"d","type":"work","g":"C"}},{"id":"n53","name":"침입·도난·범죄","kids":[{"id":"n49","name":"무단침입 발생 시 대응·경찰 신고","kids":[],"t":{"min":40,"qty":1,"unit":"건","freq":2,"per":"m","type":"work","g":"C","pick":true}},{"id":"n50","name":"도난·분실 신고 접수·조사 협조","kids":[],"t":{"min":30,"qty":1,"unit":"건","freq":1,"per":"m","type":"work","g":"C","pick":true}},{"id":"n51","name":"CCTV 영상 확인·증거 보존 지원","kids":[],"t":{"min":30,"qty":1,"unit":"건","freq":4,"per":"m","type":"work","g":"C","pick":true}},{"id":"n52","name":"수상한 물건·거동 수상자 확인","kids":[],"t":{"min":15,"qty":1,"unit":"건","freq":8,"per":"m","type":"work","g":"C","pick":true}}],"t":{"min":0,"qty":1,"unit":"회","freq":1,"per":"d","type":"work","g":"C"}},{"id":"n58","name":"소란·민원·폭력","kids":[{"id":"n54","name":"소란·난동 발생 시 제지·분리","kids":[],"t":{"min":30,"qty":1,"unit":"건","freq":1,"per":"m","type":"work","g":"C","pick":true}},{"id":"n55","name":"주취자·노숙인 대응","kids":[],"t":{"min":20,"qty":1,"unit":"건","freq":1,"per":"m","type":"work","g":"C","pick":true}},{"id":"n56","name":"현장 민원 접수·응대","kids":[],"t":{"min":10,"qty":3,"unit":"건","freq":1,"per":"d","type":"work","g":"C","pick":true}},{"id":"n57","name":"집회·시위 발생 시 출입 통제","kids":[],"t":{"min":120,"qty":1,"unit":"건","freq":1,"per":"y","type":"work","g":"C","pick":true}}],"t":{"min":0,"qty":1,"unit":"회","freq":1,"per":"d","type":"work","g":"C"}},{"id":"n63","name":"설비 이상·재난","kids":[{"id":"n59","name":"정전 시 비상조명 확인·설비팀 연락","kids":[],"t":{"min":30,"qty":1,"unit":"건","freq":2,"per":"y","type":"work","g":"C","pick":true}},{"id":"n60","name":"누수·배관 파열 초동 조치","kids":[],"t":{"min":30,"qty":1,"unit":"건","freq":3,"per":"m","type":"work","g":"C","pick":true}},{"id":"n61","name":"가스·화학물질 누출 초동 조치","kids":[],"t":{"min":60,"qty":1,"unit":"건","freq":2,"per":"y","type":"work","g":"C","pick":true}},{"id":"n62","name":"태풍·폭우 대비 시설물 결박·배수구 점검","kids":[],"t":{"min":60,"qty":6,"unit":"동","freq":3,"per":"y","type":"work","g":"C","pick":true}}],"t":{"min":0,"qty":1,"unit":"회","freq":1,"per":"d","type":"work","g":"C"}},{"id":"n66","name":"교통·주차 사고","kids":[{"id":"n64","name":"구내 교통사고 현장 통제·보고","kids":[],"t":{"min":40,"qty":1,"unit":"건","freq":1,"per":"m","type":"work","g":"C","pick":true}},{"id":"n65","name":"통행 방해·불법주차 차량 조치","kids":[],"t":{"min":5,"qty":6,"unit":"건","freq":1,"per":"d","type":"work","g":"C","pick":true}}],"t":{"min":0,"qty":1,"unit":"회","freq":1,"per":"d","type":"work","g":"C"}}],"t":{"min":0,"qty":1,"unit":"회","freq":1,"per":"d","type":"work","g":"C"}},{"id":"n80","name":"관제·방재","kids":[{"id":"n71","name":"CCTV 관제","kids":[{"id":"n68","name":"CCTV 모니터링 (정문 초소 겸무)","kids":[],"t":{"min":10,"qty":1,"unit":"회","freq":6,"per":"d","type":"work","g":"C","pick":true}},{"id":"n69","name":"CCTV 녹화 상태·카메라 점검","kids":[],"t":{"min":1,"qty":120,"unit":"대","freq":1,"per":"w","type":"work","g":"C","pick":true}},{"id":"n70","name":"영상 열람·반출 요청 처리","kids":[],"t":{"min":30,"qty":1,"unit":"건","freq":4,"per":"m","type":"work","g":"C","pick":true}}],"t":{"min":0,"qty":1,"unit":"회","freq":1,"per":"d","type":"work","g":"C"}},{"id":"n75","name":"방재·설비 감시","kids":[{"id":"n72","name":"화재수신기·방재반 감시 기록","kids":[],"t":{"min":10,"qty":1,"unit":"회","freq":3,"per":"d","type":"work","g":"C","pick":true}},{"id":"n73","name":"무인경비·침입감지 알람 확인","kids":[],"t":{"min":10,"qty":1,"unit":"건","freq":2,"per":"d","type":"work","g":"C","pick":true}},{"id":"n74","name":"비상방송·안내방송 송출","kids":[],"t":{"min":5,"qty":1,"unit":"회","freq":1,"per":"d","type":"work","g":"C","pick":true}}],"t":{"min":0,"qty":1,"unit":"회","freq":1,"per":"d","type":"work","g":"C"}},{"id":"n79","name":"소방시설 일상점검","kids":[{"id":"n76","name":"소화기·옥내소화전 외관 점검","kids":[],"t":{"min":1,"qty":125,"unit":"개","freq":1,"per":"m","type":"work","g":"C","pick":true}},{"id":"n77","name":"방화문·피난통로 적치물 확인","kids":[],"t":{"min":2,"qty":18,"unit":"층","freq":1,"per":"w","type":"work","g":"C","pick":true}},{"id":"n78","name":"유도등·비상조명 점등 확인","kids":[],"t":{"min":0.5,"qty":72,"unit":"개","freq":1,"per":"m","type":"work","g":"C","pick":true}}],"t":{"min":0,"qty":1,"unit":"회","freq":1,"per":"d","type":"work","g":"C"}}],"t":{"min":0,"qty":1,"unit":"회","freq":1,"per":"d","type":"work","g":"C"}},{"id":"n96","name":"고객사 업무 지원","kids":[{"id":"n84","name":"안내·의전","kids":[{"id":"n81","name":"VIP·귀빈 영접 및 차량 안내","kids":[],"t":{"min":20,"qty":2,"unit":"건","freq":4,"per":"m","type":"work","g":"C","pick":true}},{"id":"n82","name":"회의·행사장 출입 통제","kids":[],"t":{"min":120,"qty":2,"unit":"회","freq":1,"per":"m","type":"work","g":"C","pick":true}},{"id":"n83","name":"행사 주차 안내·교통 정리","kids":[],"t":{"min":90,"qty":1,"unit":"회","freq":1,"per":"m","type":"work","g":"C","pick":true}}],"t":{"min":0,"qty":1,"unit":"회","freq":1,"per":"d","type":"work","g":"C"}},{"id":"n89","name":"행정 지원","kids":[{"id":"n85","name":"열쇠·출입카드 보관·대여 관리","kids":[],"t":{"min":2,"qty":20,"unit":"건","freq":1,"per":"d","type":"work","g":"C","pick":true}},{"id":"n86","name":"분실물·습득물 접수·보관·반환","kids":[],"t":{"min":5,"qty":2,"unit":"건","freq":1,"per":"d","type":"work","g":"C","pick":true}},{"id":"n87","name":"공지문·게시물 부착·회수","kids":[],"t":{"min":20,"qty":6,"unit":"동","freq":2,"per":"m","type":"work","g":"C","pick":true}},{"id":"n88","name":"고객사 요청 문서·물품 전달","kids":[],"t":{"min":15,"qty":2,"unit":"건","freq":1,"per":"d","type":"work","g":"C","pick":true}}],"t":{"min":0,"qty":1,"unit":"회","freq":1,"per":"d","type":"work","g":"C"}},{"id":"n92","name":"시설·환경 지원","kids":[{"id":"n90","name":"제설·염화칼슘 살포 지원","kids":[],"t":{"min":60,"qty":2,"unit":"구역","freq":3,"per":"y","type":"work","g":"C","pick":true}},{"id":"n91","name":"시설 고장 접수·설비팀 연계","kids":[],"t":{"min":10,"qty":2,"unit":"건","freq":1,"per":"d","type":"work","g":"C","pick":true}}],"t":{"min":0,"qty":1,"unit":"회","freq":1,"per":"d","type":"work","g":"C"}},{"id":"n95","name":"업종별 특수 지원","kids":[{"id":"n93","name":"출퇴근 통근버스 통제","kids":[],"t":{"min":30,"qty":2,"unit":"회","freq":5,"per":"w","type":"work","g":"C","pick":true}},{"id":"n94","name":"협력업체 작업허가서 확인","kids":[],"t":{"min":5,"qty":10,"unit":"건","freq":5,"per":"w","type":"work","g":"C","pick":true}}],"t":{"min":0,"qty":1,"unit":"회","freq":1,"per":"d","type":"work","g":"C"}}],"t":{"min":0,"qty":1,"unit":"회","freq":1,"per":"d","type":"work","g":"C"}},{"id":"n101","name":"보고·행정·교육","kids":[{"id":"n97","name":"근무일지·인수인계","kids":[],"t":{"min":15,"qty":2,"unit":"개소","freq":3,"per":"d","type":"work","g":"C","pick":true}},{"id":"n98","name":"사건·사고 보고서 작성","kids":[],"t":{"min":30,"qty":1,"unit":"건","freq":6,"per":"m","type":"work","g":"C","pick":true}},{"id":"n99","name":"고객사 일일 업무보고","kids":[],"t":{"min":20,"qty":1,"unit":"회","freq":1,"per":"d","type":"work","g":"C","pick":true}},{"id":"n100","name":"경비원 직무교육·소방훈련 참여","kids":[],"t":{"min":240,"qty":1,"unit":"회","freq":1,"per":"q","type":"work","g":"C","pick":true}}],"t":{"min":0,"qty":1,"unit":"회","freq":1,"per":"d","type":"work","g":"C"}}],"params":{"days":30.4,"allow":15,"week":40,"loss":6,"wage":10700,"otH":0,"nightH":0,"allowance":0,"bonus":0,"pension":5,"health":3.595,"ltc":13.139999999999999,"emp":1.8499999999999999,"acc":0.86,"expense":430000,"mgmt":5,"profit":5,"plan":"precise","cFull":10,"cPartN":0,"cPartH":20}}} | B1: STEC-QUOTE v1 | C1: 3583
